<?xml version="1.0"?>
<robot name="zuros">
  	<link name="base_link">
    	<visual>
      	<geometry>
        	<box size=".7 .6 .025"/>
      	</geometry>
    	</visual>
  	</link>

	<link name="base_battery_link">
    	<visual>
      		<geometry>
        		<box size=".5 .6 .1"/>
      		</geometry>
    	</visual>
  	</link>

	<joint name="base_battery_joint" type="fixed">
    	<parent link="base_link"/>
    	<child link="base_battery_link"/>
    	<origin xyz="0.1 0 -0.0625" rpy="0 0 0" />	
  	</joint>

 	<link name="left_front_wheel">
		<visual>
		 	 <geometry>
		    	<cylinder length=".05" radius="0.1485"/>
		  	</geometry>
		  	<material name="black">
		    	<color rgba="0 0 0 1"/>
		  	</material>
		</visual>
  	</link>

	 <joint name="left_front_wheel_joint" type="continuous">
    	<parent link="base_link"/>
    	<child link="left_front_wheel"/>
		<axis xyz="0 0 1"/>
    	<origin xyz="0.25 0.325 -0.06" rpy="1.57 1.57 0" />
  	</joint>

	<link name="left_back_wheel">
    	<visual>
      		<geometry>
        		<cylinder length=".03" radius="0.0725"/>
      		</geometry>
     		<material name="black">
        		<color rgba="0 0 0 1"/>
      		</material>
    	</visual>
  	</link>

  	<joint name="left_back_wheel_joint" type="continuous">
    	<parent link="base_link"/>
    	<child link="left_back_wheel"/>
		<axis xyz="0 0 1"/>
    	<origin xyz="-0.35 0.25 -0.125" rpy="1.57 1.57 0" />	
  	</joint>

	<link name="right_front_wheel">
    	<visual>
      		<geometry>
        		<cylinder length=".05" radius="0.1485"/>
      		</geometry>
     		<material name="black">
        		<color rgba="0 0 0 1"/>
      		</material>
    	</visual>
  	</link>

  	<joint name="right_front_wheel_joint" type="continuous">
    	<parent link="base_link"/>
    	<child link="right_front_wheel"/>
		<axis xyz="0 0 1"/>	
    	<origin xyz="0.25 -0.325 -0.06" rpy="1.57 1.57 0" />	
  	</joint>

	<link name="right_back_wheel">
    	<visual>
      		<geometry>
        		<cylinder length=".03" radius="0.0725"/>
      		</geometry>
     		<material name="black">
        		<color rgba="0 0 0 1"/>
      		</material>
    	</visual>
  	</link>

  	<joint name="right_back_wheel_joint" type="continuous">
    	<parent link="base_link"/>
    	<child link="right_back_wheel"/>
		<axis xyz="0 0 1"/>
    	<origin xyz="-0.35 -0.25 -0.125" rpy="1.57 1.57 0" />	
  	</joint>

	<link name="left_back_wheel_swivel_left">
    	<visual>
      		<geometry>
        		<box size=".15 .01 0.05"/>
      		</geometry>
     		<material name="white">
        		<color rgba="1 1 1 1"/>
      		</material>
    	</visual>
  	</link>

	<link name="left_back_wheel_swivel_right">
    	<visual>
      		<geometry>
        		<box size=".15 .01 0.05"/>
      		</geometry>
     		<material name="white">
        		<color rgba="1 1 1 1"/>
      		</material>
    	</visual>
  	</link>

	<joint name="left_back_wheel_left_swivel_joint" type="fixed">
    	<parent link="base_link"/>
    	<child link="left_back_wheel_swivel_left"/>
    	<origin xyz="-0.33 0.23 -0.075" rpy="0 -1.22173048 0" />	
  	</joint>

	<joint name="left_back_wheel_right_swivel_joint" type="fixed">
    	<parent link="base_link"/>
    	<child link="left_back_wheel_swivel_right"/>
    	<origin xyz="-0.33 0.27 -0.075" rpy="0 -1.22173048 0" />	
  	</joint>

	<link name="right_back_wheel_swivel_left">
    	<visual>
      		<geometry>
        		<box size=".15 .01 0.05"/>
      		</geometry>
     		<material name="white">
        		<color rgba="1 1 1 1"/>
      		</material>
    	</visual>
  	</link>

	<link name="right_back_wheel_swivel_right">
    	<visual>
      		<geometry>
        		<box size=".15 .01 0.05"/>
      		</geometry>
     		<material name="white">
        		<color rgba="1 1 1 1"/>
      		</material>
    	</visual>
  	</link>

	<joint name="right_back_wheel_left_swivel_joint" type="fixed">
    	<parent link="base_link"/>
    	<child link="right_back_wheel_swivel_left"/>
    	<origin xyz="-0.33 -0.23 -0.075" rpy="0 -1.22173048 0" />	
  	</joint>

	<joint name="right_back_wheel_right_swivel_joint" type="fixed">
    	<parent link="base_link"/>
    	<child link="right_back_wheel_swivel_right"/>
    	<origin xyz="-0.33 -0.27 -0.075" rpy="0 -1.22173048 0" />	
  	</joint>
</robot>

